Workbook
Name _03: #REF!
Name _03: #REF!
Name _03: #REF!
Name _03: #REF!
Name _03: #REF!
Name _44242: #REF!
Name fff: #REF!
Name fff: #REF!
Name fff: #REF!
Name fff: #REF!
Name fff: #REF!
Name M: #REF!
Name M: #REF!
Name M: #REF!
Name M: #REF!
Name M: #REF!
Name импорт: #REF!
Name импорт: #REF!
Name импорт: #REF!
Name импорт: #REF!
Name импорт: #REF!
Name импорт8: #REF!
Name импорт8: #REF!
Name импорт8: #REF!
Name импорт8: #REF!
Name импорт8: #REF!

Sheet ТЗВ всего
D1: Таблица затраты-выпуcк (Input output tables)
C3: Продукты Продукты | D3: Goods/ products industry 1 | E3: Goods/ products industry 2 | F3: Goods/ products industry 3 | G3: Goods/ products industry 4 | H3: Goods/ products industry 5 | I3: Goods/ products industry 6 | J3: Goods/ products industry 7 | K3: Goods/ products industry 8 | L3: Goods/ products industry 9 | M3: Goods/ products industry 10 | N3: Goods/ products industry 11 | O3: Goods/ products industry 12 | P3: Goods/ products industry 13 | Q3: Goods/ products industry 14 | R3: Goods/ products industry 15 | S3: Goods/ products industry 16 | T3: Goods/ products industry 17 | U3: Goods/ products industry 18 | V3: Goods/ products industry 19 | W3: Goods/ products industry 20 | X3: Goods/ products industry 21 | Y3: Goods/ products industry 22 | Z3: Goods/ products industry 23 | AA3: Goods/ products industry 24 | AB3: Goods/ products industry 25 | AC3: Goods/ products industry 26 | AD3: Goods/ products industry 27 | AE3: Goods/ products industry 28 | AF3: Goods/ products industry 29 | AG3: Goods/ products industry 30 | AH3: Goods/ products industry 31 | AI3: Goods/ products industry 32 | AJ3: Goods/ products industry 33 | AK3: Goods/ products industry 34 | AL3: Goods/ products industry 35 | AM3: Goods/ products industry 36 | AN3: Goods/ products industry 37 | AO3: Goods/ products industry 38 | AP3: Goods/ products industry 39 | AQ3: Goods/ products industry 40 | AR3: Goods/ products industry 41 | AS3: Goods/ products industry 42 | AT3: Goods/ products industry 43 | AU3: Goods/ products industry 44 | AV3: Goods/ products industry 45 | AW3: Goods/ products industry 46 | AX3: Goods/ products industry 47 | AY3: Goods/ products industry 48 | AZ3: Goods/ products industry 49 | BA3: Goods/ products industry 50 | BB3: Goods/ products industry 51 | BC3: Goods/ products industry 52 | BD3: Goods/ products industry 53 | BE3: Goods/ products industry 54 | BF3: Goods/ products industry 55 | BG3: Goods/ products industry 56 | BH3: Goods/ products industry 57 | BI3: Goods/ products industry 58 | BJ3: Goods/ products industry 59 | BK3: Goods/ products industry 60 | BL3: Goods/ products industry 61 | BM3: Goods/ products industry 62 | BN3: Goods/ products industry 63 | BO3: Goods/ products industry 64 | BP3: Goods/ products industry 65 | BQ3: Goods/ products industry 66 | BR3: Goods/ products industry 67 | BS3: Goods/ products industry 68 | BT3: Goods/ products industry 69 | BU3: Goods/ products industry 70 | BV3: Goods/ products industry 71 | BW3: Goods/ products industry 72 | BX3: Goods/ products industry 73 | BY3: Goods/ products industry 74 | BZ3: Goods/ products industry 75 | CA3: Goods/ products industry 76 | CB3: Goods/ products industry 77 | CC3: Goods/ products industry 78 | CD3: Goods/ products industry 79 | CE3: Goods/ products industry 80 | CF3: Goods/ products industry 81 | CG3: Goods/ products industry 82 | CH3: Goods/ products industry 83 | CI3: Goods/ products industry 84 | CJ3: Goods/ products industry 85 | CK3: Goods/ products industry 86 | CL3: Goods/ products industry 87 | CM3: Goods/ products industry 88 | CN3: Goods/ products industry 89 | CO3: Goods/ products industry 90 | CP3: Goods/ products industry 91 | CQ3: Goods/ products industry 92 | CR3: Goods/ products industry 93 | CS3: Goods/ products industry 94 | CT3: Goods/ products industry 95 | CU3: Goods/ products industry 96 | CV3: Goods/ products industry 97 | CW3: Goods/ products industry 98 | CX3: Goods/ products industry 99 | CY3: Goods/ products industry 100 | CZ3: Goods/ products industry 101 | DA3: Goods/ products industry 102 | DB3: Goods/ products industry 103 | DC3: Goods/ products industry 104 | DD3: Goods/ products industry 105 | DE3: Goods/ products industry 106 | DF3: Goods/ products industry 107 | DG3: Goods/ products industry 108 | DH3: Goods/ products industry 109 | DI3: Goods/ products industry 110 | DJ3: Goods/ products industry 111 | DK3: Goods/ products industry 112 | DL3: Goods/ products industry 113 | DM3: Goods/ products industry 114 | DN3: Goods/ products industry 115 | DO3: Goods/ products industry 116 | DP3: Goods/ products industry 117 | DQ3: Goods/ products industry 118 | DR3: Goods/ products industry 119 | DS3: Goods/ products industry 120 | DT3: Goods/ products industry 121 | DU3: Goods/ products industry 122 | DV3: Goods/ products industry 123 | DW3: Goods/ products industry 124 | DX3: Goods/ products industry 125 | DY3: Goods/ products industry 126 | DZ3: Goods/ products industry 127 | EA3: Goods/ products industry 128 | EB3: Goods/ products industry 129 | EC3: Goods/ products industry 130 | ED3: Goods/ products industry 131 | EE3: Goods/ products industry 132 | EF3: Goods/ products industry 133 | EG3: Goods/ products industry 134 | EH3: Goods/ products industry 135 | EI3: Goods/ products industry 136 | EJ3: Промежуточный спрос | EK3: Расходы на конечное потребление | EO3: Валовое накопление | EQ3: Экспорт | ER3: Конечный спрос | ES3: Всего использовано ресурсов | ET3: Импорт товаров и услуг в основных ценах | EU3: Выпуск
EK4: домашних хозяйств | EL4: государственных учреждений | EN4: некоммерческих организаций, обслужиающих домашние хозяйства | EO4: основного капитала | EP4: изменение запасов МОС
EL5: на индивидуальные товары и услуги | EM5: на коллективные услуги | ET5: импорт
B6: Коды | D6: Code 1 | E6: Code 2 | F6: Code 3 | G6: Code 4 | H6: Code 5 | I6: Code 6 | J6: Code 7 | K6: Code 8 | L6: Code 9 | M6: Code 10 | N6: Code 11 | O6: Code 12 | P6: Code 13 | Q6: Code 14 | R6: Code 15 | S6: Code 16 | T6: Code 17 | U6: Code 18 | V6: Code 19 | W6: Code 20 | X6: Code 21 | Y6: Code 22 | Z6: Code 23 | AA6: Code 24 | AB6: Code 25 | AC6: Code 26 | AD6: Code 27 | AE6: Code 28 | AF6: Code 29 | AG6: Code 30 | AH6: Code 31 | AI6: Code 32 | AJ6: Code 33 | AK6: Code 34 | AL6: Code 35 | AM6: Code 36 | AN6: Code 37 | AO6: Code 38 | AP6: Code 39 | AQ6: Code 40 | AR6: Code 41 | AS6: Code 42 | AT6: Code 43 | AU6: Code 44 | AV6: Code 45 | AW6: Code 46 | AX6: Code 47 | AY6: Code 48 | AZ6: Code 49 | BA6: Code 50 | BB6: Code 51 | BC6: Code 52 | BD6: Code 53 | BE6: Code 54 | BF6: Code 55 | BG6: Code 56 | BH6: Code 57 | BI6: Code 58 | BJ6: Code 59 | BK6: Code 60 | BL6: Code 61 | BM6: Code 62 | BN6: Code 63 | BO6: Code 64 | BP6: Code 65 | BQ6: Code 66 | BR6: Code 67 | BS6: Code 68 | BT6: Code 69 | BU6: Code 70 | BV6: Code 71 | BW6: Code 72 | BX6: Code 73 | BY6: Code 74 | BZ6: Code 75 | CA6: Code 76 | CB6: Code 77 | CC6: Code 78 | CD6: Code 79 | CE6: Code 80 | CF6: Code 81 | CG6: Code 82 | CH6: Code 83 | CI6: Code 84 | CJ6: Code 85 | CK6: Code 86 | CL6: Code 87 | CM6: Code 88 | CN6: Code 89 | CO6: Code 90 | CP6: Code 91 | CQ6: Code 92 | CR6: Code 93 | CS6: Code 94 | CT6: Code 95 | CU6: Code 96 | CV6: Code 97 | CW6: Code 98 | CX6: Code 99 | CY6: Code 100 | CZ6: Code 101 | DA6: Code 102 | DB6: Code 103 | DC6: Code 104 | DD6: Code 105 | DE6: Code 106 | DF6: Code 107 | DG6: Code 108 | DH6: Code 109 | DI6: Code 110 | DJ6: Code 111 | DK6: Code 112 | DL6: Code 113 | DM6: Code 114 | DN6: Code 115 | DO6: Code 116 | DP6: Code 117 | DQ6: Code 118 | DR6: Code 119 | DS6: Code 120 | DT6: Code 121 | DU6: Code 122 | DV6: Code 123 | DW6: Code 124 | DX6: Code 125 | DY6: Code 126 | DZ6: Code 127 | EA6: Code 128 | EB6: Code 129 | EC6: Code 130 | ED6: Code 131 | EE6: Code 132 | EF6: Code 133 | EG6: Code 134 | EH6: Code 135 | EI6: Code 136
A7: № | D7: 1 | E7: 2 | F7: 3 | G7: 4 | H7: 5 | I7: 6 | J7: 7 | K7: 8 | L7: 9 | M7: 10 | N7: 11 | O7: 12 | P7: 13 | Q7: 14 | R7: 15 | S7: 16 | T7: 17 | U7: 18 | V7: 19 | W7: 20 | X7: 21 | Y7: 22 | Z7: 23 | AA7: 24 | AB7: 25 | AC7: 26 | AD7: 27 | AE7: 28 | AF7: 29 | AG7: 30 | AH7: 31 | AI7: 32 | AJ7: 33 | AK7: 34 | AL7: 35 | AM7: 36 | AN7: 37 | AO7: 38 | AP7: 39 | AQ7: 40 | AR7: 41 | AS7: 42 | AT7: 43 | AU7: 44 | AV7: 45 | AW7: 46 | AX7: 47 | AY7: 48 | AZ7: 49 | BA7: 50 | BB7: 51 | BC7: 52 | BD7: 53 | BE7: 54 | BF7: 55 | BG7: 56 | BH7: 57 | BI7: 58 | BJ7: 59 | BK7: 60 | BL7: 61 | BM7: 62 | BN7: 63 | BO7: 64 | BP7: 65 | BQ7: 66 | BR7: 67 | BS7: 68 | BT7: 69 | BU7: 70 | BV7: 71 | BW7: 72 | BX7: 73 | BY7: 74 | BZ7: 75 | CA7: 76 | CB7: 77 | CC7: 78 | CD7: 79 | CE7: 80 | CF7: 81 | CG7: 82 | CH7: 83 | CI7: 84 | CJ7: 85 | CK7: 86 | CL7: 87 | CM7: 88 | CN7: 89 | CO7: 90 | CP7: 91 | CQ7: 92 | CR7: 93 | CS7: 94 | CT7: 95 | CU7: 96 | CV7: 97 | CW7: 98 | CX7: 99 | CY7: 100 | CZ7: 101 | DA7: 102 | DB7: 103 | DC7: 104 | DD7: 105 | DE7: 106 | DF7: 107 | DG7: 108 | DH7: 109 | DI7: 110 | DJ7: 111 | DK7: 112 | DL7: 113 | DM7: 114 | DN7: 115 | DO7: 116 | DP7: 117 | DQ7: 118 | DR7: 119 | DS7: 120 | DT7: 121 | DU7: 122 | DV7: 123 | DW7: 124 | DX7: 125 | DY7: 126 | DZ7: 127 | EA7: 128 | EB7: 129 | EC7: 130 | ED7: 131 | EE7: 132 | EF7: 133 | EG7: 134 | EH7: 135 | EI7: 136 | EJ7: 138 | EK7: 139 | EL7: 140 | EM7: 141 | EN7: 142 | EO7: 143 | EP7: 144 | EQ7: 145 | ER7: 146 | ES7: 147
A8: 1 | B8: Code 1 | C8: Goods/ products industry 1 | D8: 1497846.5 | E8: 311524.39 | F8: 375251.56 | G8: 267422.14 | H8: 1565972.7 | I8: 421314.52 | J8: 157.24953 | K8: 37721.933 | L8: 0 | M8: 0 | N8: 0 | O8: 0 | P8: 2.9306456e-06 | Q8: 220.56964 | R8: 0 | S8: 202866.68 | T8: 9086.2839 | U8: 175999.61 | V8: 580908.19 | W8: 4518.8395 | X8: 1809405.6 | Y8: 41145.774 | Z8: 7158.9517 | AA8: 697.58785 | AB8: 242859.58 | AC8: 146528.79 | AD8: 6.6281356 | AE8: 49.862502 | AF8: 7.2484308 | AG8: 2.7410632e-06 | AH8: 94.479323 | AI8: 125.47864 | AJ8: 563.11154 | AK8: 26.43076 | AL8: 112.04762 | AM8: 4.4437097e-07 | AN8: 0 | AO8: 33.886659 | AP8: 2114.2392 | AQ8: 22.253691 | AR8: 68.598513 | AS8: 72.698916 | AT8: 0 | AU8: 17297.505 | AV8: 389.25918 | AW8: 0 | AX8: 230.50314 | AY8: 0.00028423703 | AZ8: 142.90013 | BA8: 1393.7824 | BB8: 15.742698 | BC8: 19.466886 | BD8: 0.00026752603 | BE8: 2.0378886 | BF8: 263.4742 | BG8: 0.27987604 | BH8: 126.97845 | BI8: 372.89065 | BJ8: 0.0095275498 | BK8: 2.1401141 | BL8: 16.680174 | BM8: 0.0079989135 | BN8: 206.07913 | BO8: 0.0057709769 | BP8: 0 | BQ8: 2.940393 | BR8: 18.971381 | BS8: 4.5888265 | BT8: 0.21506286 | BU8: 0 | BV8: 0.0063602359 | BW8: 2.7513155e-06 | BX8: 0 | BY8: 0.036364549 | BZ8: 1182.0773 | CA8: 0.037520376 | CB8: 0.0047211152 | CC8: 0.0055770207 | CD8: 3.5002291 | CE8: 0 | CF8: 93.059542 | CG8: 6.2413595 | CH8: 38.047946 | CI8: 0 | CJ8: 3.809903 | CK8: 145.44006 | CL8: 0 | CM8: 0 | CN8: 0 | CO8: 0.0056736587 | CP8: 84.45754 | CQ8: 104.18572 | CR8: 0.00221048 | CS8: 13.910298 | CT8: 0 | CU8: 0.0019240634 | CV8: 0 | CW8: 0 | CX8: 0 | CY8: 0 | CZ8: 55.521047 | DA8: 4925.9307 | DB8: 0 | DC8: 0 | DD8: 0 | DE8: 0 | DF8: 0 | DG8: 0 | DH8: 0 | DI8: 0 | DJ8: 0 | DK8: 0 | DL8: 0 | DM8: 0.31869093 | DN8: 1.9507967 | DO8: 28.399718 | DP8: 0 | DQ8: 5867.3401 | DR8: 0.064086699 | DS8: 389.52253 | DT8: 6.1510913 | DU8: 0.0007958256 | DV8: 0 | DW8: 946.71763 | DX8: 2.9094501 | DY8: 4610.3368 | DZ8: 4783.8626 | EA8: 1176.3175 | EB8: 0 | EC8: 480.15006 | ED8: 70.900101 | EE8: 0 | EF8: 138.20222 | EG8: 19.658185 | EH8: 18.116248 | EI8: 22.482977 | EJ8: =SUM(D8:EI8) -> 7747630.6 | EK8: Information sanitized
A9: 2 | B9: Code 2 | C9: Goods/ products industry 2 | D9: 251930.57 | E9: 4431869.7 | F9: 421276.61 | G9: 209212.94 | H9: 123772.55 | I9: 839431.58 | J9: 1083.5789 | K9: 83.43782 | L9: 0 | M9: 0 | N9: 0 | O9: 0 | P9: 0 | Q9: 151.91978 | R9: 0 | S9: 582.96927 | T9: 31.867003 | U9: 150767.61 | V9: 53.189512 | W9: 433.42924 | X9: 570.26511 | Y9: 5862.8779 | Z9: 1859.4594 | AA9: 4.203668 | AB9: 727.53649 | AC9: 804.52034 | AD9: 0.51946199 | AE9: 41.538421 | AF9: 6.5302453 | AG9: 0 | AH9: 6.3975576 | AI9: 7.3006495 | AJ9: 1.157694 | AK9: 19.910055 | AL9: 97.845336 | AM9: 0 | AN9: 0 | AO9: 0.0022433638 | AP9: 0.19912059 | AQ9: 4.0250265 | AR9: 0.011555683 | AS9: 0.079191971 | AT9: 0 | AU9: 1.7042936 | AV9: 0.025752127 | AW9: 0 | AX9: 5.110417 | AY9: 0 | AZ9: 0.22904906 | BA9: 0.99755436 | BB9: 3.7944113 | BC9: 0.00041120494 | BD9: 0 | BE9: 0.34654285 | BF9: 0.34401744 | BG9: 0.047592771 | BH9: 0.011107929 | BI9: 1.4428892 | BJ9: 0.0016177988 | BK9: 0.0001316181 | BL9: 0.0011041376 | BM9: 0 | BN9: 2.0773484 | BO9: 0 | BP9: 0 | BQ9: 0.23923323 | BR9: 2.1424887 | BS9: 0.7757604 | BT9: 0 | BU9: 0 | BV9: 0 | BW9: 0 | BX9: 0 | BY9: 0 | BZ9: 0.98767794 | CA9: 0 | CB9: 0 | CC9: 0 | CD9: 0.0068594964 | CE9: 0 | CF9: 0.187013 | CG9: 1.0112139 | CH9: 25.990585 | CI9: 0 | CJ9: 0.57099858 | CK9: 3.8919075 | CL9: 0 | CM9: 0 | CN9: 0 | CO9: 0 | CP9: 0.05356604 | CQ9: 0.21482552 | CR9: 0 | CS9: 1.7342169 | CT9: 0 | CU9: 0 | CV9: 0 | CW9: 0 | CX9: 0 | CY9: 0 | CZ9: 1151.0101 | DA9: 124320.82 | DB9: 0 | DC9: 0 | DD9: 0.0083963098 | DE9: 0 | DF9: 0 | DG9: 0 | DH9: 0 | DI9: 0 | DJ9: 0 | DK9: 0 | DL9: 7.2622878 | DM9: 0 | DN9: 5.6678435 | DO9: 8.9375722 | DP9: 0 | DQ9: 13865.713 | DR9: 0.14727257 | DS9: 280.26468 | DT9: 0 | DU9: 0.0015056075 | DV9: 0 | DW9: 0 | DX9: 3.4515783 | DY9: 197791.43 | DZ9: 87224.059 | EA9: 11966.113 | EB9: 421.46779 | EC9: 7935.3075 | ED9: 861.60777 | EE9: 0 | EF9: 1353.7088 | EG9: 29.769356 | EH9: 0 | EI9: 948.79844 | EJ9: =SUM(D9:EI9) -> 6888925.8
A10: 3 | B10: Code 3 | C10: Goods/ products industry 3 | D10: 403832.48 | E10: 5973.9516 | F10: 216019.81 | G10: 0 | H10: 0 | I10: 1648.8603 | J10: 0 | K10: 0 | L10: 0 | M10: 0 | N10: 0 | O10: 0 | P10: 0 | Q10: 0.79495376 | R10: 0 | S10: 133.50644 | T10: 0 | U10: 4.7070421 | V10: 90299.264 | W10: 0.056209429 | X10: 0.6673336 | Y10: 69.692767 | Z10: 39.291104 | AA10: 0 | AB10: 0 | AC10: 1.6497753 | AD10: 0 | AE10: 4301187.8 | AF10: 122953.77 | AG10: 1975.9863 | AH10: 190461.71 | AI10: 24918.92 | AJ10: 180.12524 | AK10: 0.58739806 | AL10: 1945.1383 | AM10: 206.55105 | AN10: 0 | AO10: 0 | AP10: 35.973939 | AQ10: 0 | AR10: 7.7728113 | AS10: 0 | AT10: 30.642103 | AU10: 5.4285542 | AV10: 81.127641 | AW10: 17117.792 | AX10: 2.2645922 | AY10: 750.23378 | AZ10: 655.70243 | BA10: 3439.2044 | BB10: 10.627769 | BC10: 225.32958 | BD10: 0.06625091 | BE10: 22.610691 | BF10: 0 | BG10: 0.06625091 | BH10: 128.00659 | BI10: 27.580014 | BJ10: 0 | BK10: 4.7808596 | BL10: 0.93177368 | BM10: 0.025829734 | BN10: 0 | BO10: 0 | BP10: 3.870829 | BQ10: 23.641641 | BR10: 9.1793904 | BS10: 7.1452664 | BT10: 0.0067972985 | BU10: 0 | BV10: 0 | BW10: 0 | BX10: 0 | BY10: 0.0067972985 | BZ10: 67.995577 | CA10: 3.8743242 | CB10: 0.29445897 | CC10: 0 | CD10: 0.96606218 | CE10: 87.924027 | CF10: 0.0067972985 | CG10: 790.26433 | CH10: 33.263768 | CI10: 0.28581066 | CJ10: 114.7249 | CK10: 0.12914867 | CL10: 0 | CM10: 64.545244 | CN10: 0 | CO10: 0 | CP10: 821.97077 | CQ10: 0 | CR10: 0 | CS10: 19439.154 | CT10: 0 | CU10: 0 | CV10: 0 | CW10: 0 | CX10: 0 | CY10: 0 | CZ10: 0 | DA10: 0 | DB10: 0 | DC10: 0 | DD10: 0 | DE10: 0 | DF10: 0 | DG10: 0 | DH10: 0 | DI10: 0 | DJ10: 0 | DK10: 0 | DL10: 0 | DM10: 0 | DN10: 0 | DO10: 6.9832192 | DP10: 0 | DQ10: 0 | DR10: 0 | DS10: 0 | DT10: 0 | DU10: 0 | DV10: 0 | DW10: 0 | DX10: 0 | DY10: 0 | DZ10: 0.20993857 | EA10: 0 | EB10: 0 | EC10: 0 | ED10: 0 | EE10: 0 | EF10: 0 | EG10: 0 | EH10: 0 | EI10: 0 | EJ10: =SUM(D10:EI10) -> 5405877.9
A11: 4 | B11: Code 4 | C11: Goods/ products industry 4 | D11: 5590.6908 | E11: 77355.102 | F11: 29.063222 | G11: 112020.66 | H11: 6886.5132 | I11: 50719.889 | J11: 0 | K11: 52.189911 | L11: 0 | M11: 0 | N11: 0 | O11: 0 | P11: 0 | Q11: 92.359251 | R11: 0 | S11: 84.460756 | T11: 0 | U11: 93082.005 | V11: 1.6109434 | W11: 262.95469 | X11: 115.73215 | Y11: 177.65844 | Z11: 632.49313 | AA11: 102.77394 | AB11: 34.429475 | AC11: 649407.37 | AD11: 0.38186882 | AE11: 25.31387 | AF11: 4.0219238 | AG11: 0 | AH11: 0.022962738 | AI11: 3.8086349 | AJ11: 0.00012309814 | AK11: 12.266957 | AL11: 68.897771 | AM11: 0 | AN11: 0 | AO11: 0 | AP11: 67.407706 | AQ11: 2.3687938 | AR11: 0.00070736461 | AS11: 329.84818 | AT11: 0 | AU11: 9.0652279 | AV11: 1.7806925 | AW11: 0 | AX11: 0.0023563067 | AY11: 0 | AZ11: 568.72419 | BA11: 4181.9268 | BB11: 0 | BC11: 88.777623 | BD11: 0 | BE11: 0.0012440903 | BF11: 0.0037752557 | BG11: 0.00017085825 | BH11: 0 | BI11: 0.026958762 | BJ11: 5.8079047e-06 | BK11: 0 | BL11: 0 | BM11: 0 | BN11: 0 | BO11: 0 | BP11: 0 | BQ11: 0.00030844636 | BR11: 0.0075736232 | BS11: 0.0027849832 | BT11: 0 | BU11: 0 | BV11: 0 | BW11: 0 | BX11: 0 | BY11: 0 | BZ11: 15.148415 | CA11: 0 | CB11: 0 | CC11: 0 | CD11: 0 | CE11: 0 | CF11: 5.047304e-06 | CG11: 0.0031658365 | CH11: 11.332782 | CI11: 0 | CJ11: 0.0017525361 | CK11: 1.6380661 | CL11: 0 | CM11: 0 | CN11: 0 | CO11: 0 | CP11: 7.4270966 | CQ11: 455.58683 | CR11: 0 | CS11: 0.0062619104 | CT11: 0 | CU11: 0 | CV11: 0 | CW11: 0 | CX11: 0 | CY11: 0 | CZ11: 17.612116 | DA11: 0 | DB11: 0 | DC11: 0 | DD11: 0.020602333 | DE11: 0 | DF11: 0 | DG11: 0 | DH11: 0 | DI11: 0 | DJ11: 0 | DK11: 0 | DL11: 0 | DM11: 0 | DN11: 0 | DO11: 0.1217217 | DP11: 0 | DQ11: 5147.6641 | DR11: 0 | DS11: 280.91978 | DT11: 0 | DU11: 0.0034495706 | DV11: 0 | DW11: 0 | DX11: 0 | DY11: 23005.961 | DZ11: 1821.7965 | EA11: 137.01248 | EB11: 0 | EC11: 0 | ED11: 1.2080013 | EE11: 0 | EF11: 73.999242 | EG11: 0.45989022 | EH11: 0 | EI11: 0.96680841 | EJ11: =SUM(D11:EI11) -> 1032991.5
A12: 5 | B12: Code 5 | C12: Goods/ products industry 5 | D12: 208951.91 | E12: 166620.61 | F12: 9123.8446 | G12: 66314.215 | H12: 11362093 | I12: 406786.67 | J12: 3867.3897 | K12: 7991.8169 | L12: 0 | M12: 0 | N12: 0 | O12: 0 | P12: 0.26692161 | Q12: 308.014 | R12: 0.034863684 | S12: 983620.76 | T12: 8202.4399 | U12: 1229.9427 | V12: 252958.73 | W12: 627662.79 | X12: 2593.3434 | Y12: 20466.206 | Z12: 18723.208 | AA12: 24.825596 | AB12: 20118.054 | AC12: 8977.417 | AD12: 5.7934324 | AE12: 114615.65 | AF12: 8311.3448 | AG12: 175.13872 | AH12: 4869.5592 | AI12: 3955.6728 | AJ12: 124680.71 | AK12: 0.1519361 | AL12: 988.37892 | AM12: 2.3270761 | AN12: 0 | AO12: 14.902484 | AP12: 1861.6096 | AQ12: 114.99166 | AR12: 9.0473442 | AS12: 1.0141152 | AT12: 0.34582158 | AU12: 7678.0113 | AV12: 173.99053 | AW12: 436.21608 | AX12: 207.11296 | AY12: 39.759828 | AZ12: 49.931536 | BA12: 710.18822 | BB12: 53.784894 | BC12: 4.6699665 | BD12: 0.0063337503 | BE12: 1.3989187 | BF12: 1234.7756 | BG12: 0.15801432 | BH12: 59.150448 | BI12: 481.24851 | BJ12: 0.0061814918 | BK12: 1.2205604 | BL12: 7.388319 | BM12: 146.78291 | BN12: 26.336674 | BO12: 0.029905137 | BP12: 0.0434354 | BQ12: 12.112857 | BR12: 137.28904 | BS12: 2.6436885 | BT12: 0.001481392 | BU12: 0 | BV12: 0 | BW12: 0 | BX12: 0 | BY12: 0.00017392216 | BZ12: 16.778092 | CA12: 0.099132154 | CB12: 0.0075343081 | CC12: 0 | CD12: 17.133392 | CE12: 566.59968 | CF12: 462.07742 | CG12: 24.819857 | CH12: 94.472127 | CI12: 0.0032071425 | CJ12: 6.9465021 | CK12: 14.912118 | CL12: 0 | CM12: 1.6550755 | CN12: 0 | CO12: 0.00035792871 | CP12: 208.19111 | CQ12: 1.0443405 | CR12: 0.19072572 | CS12: 1367.1777 | CT12: 0 | CU12: 0 | CV12: 0 | CW12: 0 | CX12: 0 | CY12: 0 | CZ12: 267.06127 | DA12: 410909.89 | DB12: 0 | DC12: 0 | DD12: 0.1188045 | DE12: 0 | DF12: 0 | DG12: 0 | DH12: 0 | DI12: 0 | DJ12: 0 | DK12: 0 | DL12: 0 | DM12: 0 | DN12: 0 | DO12: 161.20744 | DP12: 0 | DQ12: 0 | DR12: 94.336738 | DS12: 44.100532 | DT12: 5.7040257 | DU12: 0 | DV12: 0 | DW12: 0 | DX12: 0 | DY12: 220211.18 | DZ12: 370008.72 | EA12: 56776.1 | EB12: 504.03043 | EC12: 1010.1278 | ED12: 3046.6391 | EE12: 241.58086 | EF12: 8133.2083 | EG12: 3.6947213 | EH12: 0 | EI12: 0 | EJ12: =SUM(D12:EI12) -> 15521906
A13: 6 | B13: Code 6 | C13: Goods/ products industry 6 | D13: 595563.55 | E13: 1767962.5 | F13: 689429.08 | G13: 699545.39 | H13: 3029674.8 | I13: 2985459 | J13: 79046.335 | K13: 8666.0449 | L13: 11.950111 | M13: 1.0235125 | N13: 6.0188344 | O13: 0 | P13: 0.012504484 | Q13: 232.89151 | R13: 0.69899179 | S13: 8974.9444 | T13: 1094.0476 | U13: 174920.46 | V13: 2845.2176 | W13: 698.45258 | X13: 8867.3281 | Y13: 10294.833 | Z13: 12924.641 | AA13: 36.61802 | AB13: 17276.355 | AC13: 99376.739 | AD13: 22306.647 | AE13: 7010.6598 | AF13: 231.18492 | AG13: 4.6172417 | AH13: 982.60563 | AI13: 255.7442 | AJ13: 420.20964 | AK13: 6341.9619 | AL13: 586.97765 | AM13: 3.5155729 | AN13: 0.00016590354 | AO13: 16.702834 | AP13: 1068.7031 | AQ13: 8379.2634 | AR13: 675.62239 | AS13: 224.74145 | AT13: 0.469149 | AU13: 1965.499 | AV13: 217.47166 | AW13: 31.902438 | AX13: 29456.701 | AY13: 3872.1617 | AZ13: 4196.745 | BA13: 839.62467 | BB13: 95.511974 | BC13: 314.06906 | BD13: 1.0286001 | BE13: 14.94881 | BF13: 5.7451895 | BG13: 2.9454396 | BH13: 0.81115454 | BI13: 16.350845 | BJ13: 0.12484103 | BK13: 3.7461701 | BL13: 4.2646453 | BM13: 14.86047 | BN13: 75.892238 | BO13: 22.829053 | BP13: 0.049658437 | BQ13: 202.29157 | BR13: 62.278341 | BS13: 16.114376 | BT13: 4.2160299 | BU13: 3.3911519 | BV13: 15.406718 | BW13: 29.385838 | BX13: 61.733775 | BY13: 7.2094517 | BZ13: 771.20429 | CA13: 16.119165 | CB13: 11.651627 | CC13: 8.2648231 | CD13: 0.25744723 | CE13: 15.96419 | CF13: 5.3622095 | CG13: 1056.7302 | CH13: 246.68117 | CI13: 545.68419 | CJ13: 69.922486 | CK13: 81.860041 | CL13: 7284.8816 | CM13: 0.3682216 | CN13: 0 | CO13: 0.00026259297 | CP13: 90.716592 | CQ13: 75.644224 | CR13: 14.165633 | CS13: 52.542146 | CT13: 3.9493202 | CU13: 9384.3644 | CV13: 73869.086 | CW13: 8974.4692 | CX13: 0 | CY13: 0 | CZ13: 517.97144 | DA13: 17413.585 | DB13: 0.0026923282 | DC13: 5.962764 | DD13: 119.43112 | DE13: 0.00076251329 | DF13: 27.603602 | DG13: 3.461289 | DH13: 47.418166 | DI13: 0 | DJ13: 36.206428 | DK13: 1023.6932 | DL13: 66.431978 | DM13: 0 | DN13: 37.878862 | DO13: 4481.335 | DP13: 14.06954 | DQ13: 22338.077 | DR13: 0.49030789 | DS13: 950.77857 | DT13: 0 | DU13: 62.94267 | DV13: 0 | DW13: 50309.444 | DX13: 2446.7931 | DY13: 295876.06 | DZ13: 65005.779 | EA13: 2445.3965 | EB13: 599.52564 | EC13: 1104.9521 | ED13: 839.46057 | EE13: 6.0028122 | EF13: 1083.9261 | EG13: 82.457165 | EH13: 327.27166 | EI13: 6600.2046 | EJ13: =SUM(D13:EI13) -> 10859428
A14: 7 | B14: Code 7 | C14: Goods/ products industry 7 | D14: 0.31572756 | E14: 14593.634 | F14: 0 | G14: 177.09034 | H14: 50790.444 | I14: 3809.5949 | J14: 577097.29 | K14: 136.39341 | L14: 5368.4814 | M14: 87.857296 | N14: 802.58687 | O14: 0 | P14: 4623.9629 | Q14: 6441.5938 | R14: 38.019192 | S14: 0.66806576 | T14: 0 | U14: 107.79441 | V14: 132.75611 | W14: 6.5781102 | X14: 41.533254 | Y14: 1874.7359 | Z14: 112.02601 | AA14: 1.0134927 | AB14: 6.3997773 | AC14: 21.728636 | AD14: 0 | AE14: 13.380419 | AF14: 2.1693272 | AG14: 0.00037307121 | AH14: 81.25283 | AI14: 15.456522 | AJ14: 83.145296 | AK14: 158859.37 | AL14: 6350.8383 | AM14: 8.4570196 | AN14: 0.002206428 | AO14: 125.0254 | AP14: 706.72351 | AQ14: 71.465028 | AR14: 1362.423 | AS14: 2.9143544 | AT14: 93614.342 | AU14: 624.64141 | AV14: 2230.4273 | AW14: 0.00049347755 | AX14: 6.2510786 | AY14: 415.16093 | AZ14: 10702.251 | BA14: 49.063607 | BB14: 526.01625 | BC14: 36.295553 | BD14: 22.410046 | BE14: 370.54569 | BF14: 114.43632 | BG14: 88.956015 | BH14: 2362.4663 | BI14: 5194.3299 | BJ14: 48.405906 | BK14: 785.41024 | BL14: 19.512546 | BM14: 6.2400054 | BN14: 65.180791 | BO14: 410.62111 | BP14: 0 | BQ14: 342.51154 | BR14: 2644.9224 | BS14: 299.3992 | BT14: 19.31124 | BU14: 0.21062003 | BV14: 66.698975 | BW14: 24.402365 | BX14: 1209.0368 | BY14: 1.7981505 | BZ14: 1040.9249 | CA14: 1.603531 | CB14: 94.501486 | CC14: 14.646853 | CD14: 1.2979207 | CE14: 75.618924 | CF14: 12807.508 | CG14: 21194.363 | CH14: 85.785951 | CI14: 184.48941 | CJ14: 55.358481 | CK14: 895.46849 | CL14: 4.7899181 | CM14: 0 | CN14: 0 | CO14: 0 | CP14: 120.55009 | CQ14: 0.11228136 | CR14: 0.0023949544 | CS14: 916.49766 | CT14: 0 | CU14: 723743.74 | CV14: 0 | CW14: 426.64789 | CX14: 0 | CY14: 0 | CZ14: 23.489921 | DA14: 324.20366 | DB14: 0 | DC14: 0 | DD14: 0 | DE14: 0 | DF14: 0 | DG14: 0 | DH14: 0 | DI14: 0 | DJ14: 0 | DK14: 10086.546 | DL14: 0 | DM14: 0 | DN14: 0 | DO14: 0 | DP14: 0 | DQ14: 10.803266 | DR14: 0 | DS14: 0 | DT14: 0 | DU14: 0 | DV14: 0 | DW14: 5109.5434 | DX14: 0 | DY14: 754.46604 | DZ14: 38.886249 | EA14: 44.352599 | EB14: 0 | EC14: 0 | ED14: 17.94241 | EE14: 0 | EF14: 0 | EG14: 0 | EH14: 0 | EI14: 0 | EJ14: =SUM(D14:EI14) -> 1734330.5
A15: 8 | B15: Code 8 | C15: Goods/ products industry 8 | D15: 700.86139 | E15: 4967.4747 | F15: 57.815041 | G15: 208.39821 | H15: 45826.869 | I15: 1235.5986 | J15: 0 | K15: 174246.96 | L15: 0 | M15: 0 | N15: 0 | O15: 0 | P15: 0 | Q15: 0.89663018 | R15: 0 | S15: 134.95409 | T15: 992.37772 | U15: 2.9242128 | V15: 0.092284997 | W15: 1.2938368 | X15: 0.45654314 | Y15: 21.902903 | Z15: 226.29691 | AA15: 0.26464091 | AB15: 10.703282 | AC15: 0.11944144 | AD15: 0 | AE15: 0.00024289747 | AF15: 0.00088083746 | AG15: 0 | AH15: 0 | AI15: 0.25111484 | AJ15: 0.37474661 | AK15: 0 | AL15: 0.16348004 | AM15: 0 | AN15: 0 | AO15: 0 | AP15: 0.012958904 | AQ15: 0.0026595138 | AR15: 0 | AS15: 0.016125305 | AT15: 0 | AU15: 0.12472592 | AV15: 0 | AW15: 0 | AX15: 1.0987091 | AY15: 0 | AZ15: 0.00023410962 | BA15: 0.18965349 | BB15: 0.8217627 | BC15: 0 | BD15: 0 | BE15: 0 | BF15: 0 | BG15: 0 | BH15: 0.00058527406 | BI15: 0.10941175 | BJ15: 0 | BK15: 0 | BL15: 0 | BM15: 0 | BN15: 0.030472785 | BO15: 0 | BP15: 0 | BQ15: 0.033203885 | BR15: 0.00098107728 | BS15: 0 | BT15: 0 | BU15: 0 | BV15: 0 | BW15: 0 | BX15: 0 | BY15: 0 | BZ15: 0.091781858 | CA15: 0 | CB15: 0 | CC15: 0 | CD15: 0.0022881983 | CE15: 0 | CF15: 0.061824005 | CG15: 0.028612761 | CH15: 2.0324421 | CI15: 0 | CJ15: 0.016089627 | CK15: 0.016980347 | CL15: 0 | CM15: 0 | CN15: 0 | CO15: 0 | CP15: 0.010408748 | CQ15: 0.0059894606 | CR15: 0 | CS15: 0 | CT15: 0 | CU15: 0 | CV15: 0 | CW15: 0 | CX15: 0 | CY15: 0 | CZ15: 182.98692 | DA15: 9563.933 | DB15: 0 | DC15: 0 | DD15: 0 | DE15: 0 | DF15: 0 | DG15: 0 | DH15: 0 | DI15: 0 | DJ15: 0 | DK15: 0 | DL15: 0 | DM15: 0 | DN15: 0 | DO15: 0 | DP15: 0 | DQ15: 0 | DR15: 0 | DS15: 10.408335 | DT15: 0 | DU15: 0 | DV15: 0 | DW15: 0 | DX15: 42.835078 | DY15: 7.7367676 | DZ15: 9664.8454 | EA15: 583.30906 | EB15: 0 | EC15: 68.449407 | ED15: 14.304797 | EE15: 0 | EF15: 253.18118 | EG15: 0.92582196 | EH15: 0 | EI15: 4.4700429 | EJ15: =SUM(D15:EI15) -> 249039.14
A16: 9 | B16: Code 9 | C16: Goods/ products industry 9 | D16: 359.67872 | E16: 373.1068 | F16: 172.86363 | G16: 0 | H16: 529.93476 | I16: 279.55288 | J16: 196.04259 | K16: 550.13437 | L16: 64.860199 | M16: 128.19567 | N16: 1207.3091 | O16: 0 | P16: 42.330027 | Q16: 607.09246 | R16: 37.171446 | S16: 0.76839425 | T16: 0 | U16: 126.53212 | V16: 292.32547 | W16: 2.0297863 | X16: 44.581921 | Y16: 147.30255 | Z16: 4.7280817 | AA16: 0.19324204 | AB16: 6.3769789 | AC16: 0.80328273 | AD16: 0 | AE16: 100.66339 | AF16: 8.8901988 | AG16: 5.3112988 | AH16: 83.259861 | AI16: 1211.575 | AJ16: 2.9829253 | AK16: 477.88916 | AL16: 19.610891 | AM16: 0.1800296 | AN16: 0 | AO16: 132.39386 | AP16: 243.25459 | AQ16: 382.94984 | AR16: 2032.3797 | AS16: 0.54733397 | AT16: 24.34049 | AU16: 8.8891182 | AV16: 23.80613 | AW16: 0.57194733 | AX16: 0.33882687 | AY16: 5.0311969 | AZ16: 164.35321 | BA16: 19.940495 | BB16: 126.23598 | BC16: 10.993295 | BD16: 15.89739 | BE16: 61.632723 | BF16: 3026.5086 | BG16: 280.70724 | BH16: 3600.408 | BI16: 305.32938 | BJ16: 131.39692 | BK16: 114.22417 | BL16: 2713.4595 | BM16: 79.316073 | BN16: 97.022152 | BO16: 1039.1728 | BP16: 19.894678 | BQ16: 1068.7134 | BR16: 355.48624 | BS16: 1.7143354 | BT16: 33.519202 | BU16: 0.059632365 | BV16: 10.949483 | BW16: 0.15847491 | BX16: 3.9475761 | BY16: 0.41554219 | BZ16: 11.862696 | CA16: 2.7124149 | CB16: 0.62648974 | CC16: 1.4890199 | CD16: 0.7176846 | CE16: 3.6250701 | CF16: 5.3466265 | CG16: 23.73398 | CH16: 44.374285 | CI16: 1.0097193 | CJ16: 6.0821963 | CK16: 306.0039 | CL16: 276587.9 | CM16: 1.2795083 | CN16: 1500.3565 | CO16: 0.064831961 | CP16: 4485.4725 | CQ16: 8.5038731 | CR16: 0.74729466 | CS16: 12.048909 | CT16: 0 | CU16: 34795.185 | CV16: 32017.423 | CW16: 13981.575 | CX16: 11585.287 | CY16: 39.881126 | CZ16: 100.77782 | DA16: 406.09632 | DB16: 0.0012377469 | DC16: 18.756651 | DD16: 0.78671948 | DE16: 0 | DF16: 52.591935 | DG16: 0 | DH16: 117.21386 | DI16: 0 | DJ16: 0 | DK16: 1486.3432 | DL16: 0 | DM16: 0 | DN16: 108.58343 | DO16: 11.374683 | DP16: 40.506822 | DQ16: 118.5069 | DR16: 5.2300588 | DS16: 39.165977 | DT16: 0 | DU16: 0 | DV16: 0 | DW16: 78.941009 | DX16: 0 | DY16: 38639.169 | DZ16: 145994.84 | EA16: 10409.68 | EB16: 465.22386 | EC16: 98.225711 | ED16: 173.62991 | EE16: 578.52724 | EF16: 878.35493 | EG16: 45.534544 | EH16: 0 | EI16: 67508.5 | EJ16: =SUM(D16:EI16) -> 666020.11
A17: 10 | B17: Code 10 | C17: Goods/ products industry 10 | D17: 0 | E17: 0 | F17: 0 | G17: 0 | H17: 0 | I17: 0 | J17: 0 | K17: 0.015564283 | L17: 0 | M17: 6133.6604 | N17: 59755.472 | O17: 0 | P17: 0 | Q17: 1724.1711 | R17: 5.3479483 | S17: 0.020994652 | T17: 0 | U17: 9.2810904 | V17: 0.14496156 | W17: 0.028331839 | X17: 0.18736141 | Y17: 4.9365009 | Z17: 0.0002449844 | AA17: 0 | AB17: 0.00013676643 | AC17: 3.3146482e-07 | AD17: 0 | AE17: 1814.7992 | AF17: 17.172213 | AG17: 0 | AH17: 52.435119 | AI17: 30.107119 | AJ17: 6.1108617 | AK17: 107.48463 | AL17: 44.1808 | AM17: 1.2301081e-05 | AN17: 46.889567 | AO17: 1706780.2 | AP17: 408.77097 | AQ17: 1.1427602 | AR17: 99089.01 | AS17: 0.00014824094 | AT17: 110.45759 | AU17: 9.3930692 | AV17: 11163.138 | AW17: 1348.371 | AX17: 0.0025077691 | AY17: 3.252607 | AZ17: 1347.3196 | BA17: 37.906384 | BB17: 49.312378 | BC17: 832.74934 | BD17: 8993.9978 | BE17: 32.57377 | BF17: 617.07614 | BG17: 183.36357 | BH17: 1187.2839 | BI17: 1286.6122 | BJ17: 22.711478 | BK17: 6815.2946 | BL17: 1.1991124 | BM17: 18.696686 | BN17: 2.6572525 | BO17: 112.07134 | BP17: 0 | BQ17: 23.05187 | BR17: 7.3641759 | BS17: 58.587199 | BT17: 3.2895527 | BU17: 9.2941937 | BV17: 0.0029923909 | BW17: 5.1234912 | BX17: 0 | BY17: 1.7078304 | BZ17: 3.4101908 | CA17: 0 | CB17: 0 | CC17: 0 | CD17: 0 | CE17: 0.60246805 | CF17: 0.13311555 | CG17: 3.5418149 | CH17: 371.39621 | CI17: 8.1769492 | CJ17: 0.037324207 | CK17: 105.98701 | CL17: 35168.804 | CM17: 1.0317125 | CN17: 0 | CO17: 0 | CP17: 497.56813 | CQ17: 16.581847 | CR17: 58.906728 | CS17: 439.39053 | CT17: 0 | CU17: 0 | CV17: 0 | CW17: 0 | CX17: 0 | CY17: 0 | CZ17: 0 | DA17: 0 | DB17: 0 | DC17: 0 | DD17: 0 | DE17: 0 | DF17: 0 | DG17: 0 | DH17: 0 | DI17: 0 | DJ17: 0 | DK17: 0 | DL17: 0 | DM17: 0 | DN17: 0 | DO17: 0 | DP17: 0 | DQ17: 0 | DR17: 0 | DS17: 0 | DT17: 0 | DU17: 0 | DV17: 0 | DW17: 0 | DX17: 0 | DY17: 0 | DZ17: 0 | EA17: 0 | EB17: 0 | EC17: 0 | ED17: 0 | EE17: 0 | EF17: 0 | EG17: 0 | EH17: 0 | EI17: 0 | EJ17: =SUM(D17:EI17) -> 1946991
A18: 11 | B18: Code 11 | C18: Goods/ products industry 11 | D18: 1937.6686 | E18: 26146.099 | F18: 682.36675 | G18: 116.96931 | H18: 30297.202 | I18: 16307.437 | J18: 3642.7111 | K18: 1482.2582 | L18: 543.17112 | M18: 148048.01 | N18: 689541.48 | O18: 0 | P18: 42114.2 | Q18: 12373.469 | R18: 3384.7807 | S18: 506.03869 | T18: 31.845308 | U18: 4785.7644 | V18: 4068.786 | W18: 2370.968 | X18: 2243.4689 | Y18: 76386.031 | Z18: 6847.3623 | AA18: 6494.9028 | AB18: 396.79326 | AC18: 2970.0757 | AD18: 414.41058 | AE18: 6887.6458 | AF18: 1929.4467 | AG18: 2410.8006 | AH18: 3403.7145 | AI18: 1870.1849 | AJ18: 589.12976 | AK18: 666.88503 | AL18: 2670.3912 | AM18: 25.880714 | AN18: 0.012186775 | AO18: 126948 | AP18: 21007.339 | AQ18: 59933.101 | AR18: 75698.219 | AS18: 258.10834 | AT18: 2786.0452 | AU18: 2280.0431 | AV18: 2289.4149 | AW18: 1163.9342 | AX18: 3819.3943 | AY18: 729.07592 | AZ18: 5892.1317 | BA18: 198.23402 | BB18: 1726.497 | BC18: 639.62026 | BD18: 9818.182 | BE18: 6399.0221 | BF18: 37858.175 | BG18: 6591.7334 | BH18: 231406.1 | BI18: 152352.68 | BJ18: 2310.3543 | BK18: 13133.823 | BL18: 9830.5155 | BM18: 1211.6479 | BN18: 1999.9945 | BO18: 456112.59 | BP18: 468.42818 | BQ18: 6571.5887 | BR18: 13778.975 | BS18: 1781.6312 | BT18: 595.81139 | BU18: 608.96765 | BV18: 7231.6309 | BW18: 887.1542 | BX18: 2792.6744 | BY18: 21.068336 | BZ18: 1283.6287 | CA18: 195.70322 | CB18: 106.15647 | CC18: 338.75353 | CD18: 18.452411 | CE18: 305.00684 | CF18: 1699.2387 | CG18: 2548.8999 | CH18: 1362.1756 | CI18: 347.75942 | CJ18: 529.66772 | CK18: 7147.224 | CL18: 1321664.6 | CM18: 9989.4403 | CN18: 231.57099 | CO18: 60243.967 | CP18: 290358.08 | CQ18: 4282.9793 | CR18: 2198.2237 | CS18: 2114.3741 | CT18: 20.610013 | CU18: 28280.21 | CV18: 449936.44 | CW18: 775824.07 | CX18: 13672.44 | CY18: 310.2378 | CZ18: 150.66509 | DA18: 5553.8975 | DB18: 283.40788 | DC18: 58.374715 | DD18: 327.42607 | DE18: 283.77497 | DF18: 227.15608 | DG18: 35.408916 | DH18: 2578.1031 | DI18: 738.55499 | DJ18: 126.16429 | DK18: 7798.1997 | DL18: 39.285833 | DM18: 17.793625 | DN18: 992.31326 | DO18: 2521.0228 | DP18: 33.594637 | DQ18: 35.550585 | DR18: 86.248216 | DS18: 16852.981 | DT18: 470.53732 | DU18: 38.590258 | DV18: 0 | DW18: 2468.547 | DX18: 190.73147 | DY18: 111018.35 | DZ18: 119518.7 | EA18: 22359.575 | EB18: 1764.6265 | EC18: 368.46043 | ED18: 492.971 | EE18: 1328.0963 | EF18: 3429.0412 | EG18: 1126.7665 | EH18: 570.69546 | EI18: 20554.846 | EJ18: =SUM(D18:EI18) -> 5673170.6
A19: 12 | B19: Code 12 | C19: Goods/ products industry 12 | D19: 0 | E19: 0 | F19: 0 | G19: 0 | H19: 0 | I19: 0 | J19: 0 | K19: 0 | L19: 0 | M19: 0 | N19: 0.0012302091 | O19: 0 | P19: 0.0089676994 | Q19: 4.2736362 | R19: 0 | S19: 8.9799989 | T19: 0 | U19: 0.0012271451 | V19: 0 | W19: 0.00034007068 | X19: 0 | Y19: 0.0024280026 | Z19: 0 | AA19: 0 | AB19: 0 | AC19: 0 | AD19: 0 | AE19: 1.364967 | AF19: 0 | AG19: 0 | AH19: 28.215092 | AI19: 0.10494888 | AJ19: 0.00033114381 | AK19: 5.0026794 | AL19: 0.019825265 | AM19: 0 | AN19: 0.039556313 | AO19: 1296.5716 | AP19: 66.683555 | AQ19: 0 | AR19: 0.1807653 | AS19: 0 | AT19: 0.00015337188 | AU19: 0 | AV19: 15.534182 | AW19: 0 | AX19: 0 | AY19: 0.079437923 | AZ19: 4.5519355 | BA19: 0.0007301451 | BB19: 5.8490332 | BC19: 0.10618054 | BD19: 0.059586134 | BE19: 0.0013770602 | BF19: 0.00092564519 | BG19: 0 | BH19: 0.77544299 | BI19: 42.414053 | BJ19: 0.92140619 | BK19: 616.11069 | BL19: 68729.762 | BM19: 1945.149 | BN19: 1205.1273 | BO19: 1916.5044 | BP19: 766.03815 | BQ19: 17655.074 | BR19: 1192.1348 | BS19: 4.2122961 | BT19: 0 | BU19: 0 | BV19: 0.12797613 | BW19: 0.0047935785 | BX19: 1.4130036 | BY19: 0 | BZ19: 4.5215993 | CA19: 0.025355818 | CB19: 0.51895908 | CC19: 0.0017892819 | CD19: 0 | CE19: 0.035017166 | CF19: 0.00026737377 | CG19: 0.066217173 | CH19: 0.72588091 | CI19: 0 | CJ19: 0.00029716056 | CK19: 8.6603491 | CL19: 0 | CM19: 0 | CN19: 0 | CO19: 0 | CP19: 0.0077609555 | CQ19: 0.020152187 | CR19: 0.044823281 | CS19: 151.87938 | CT19: 0 | CU19: 0 | CV19: 0 | CW19: 0 | CX19: 0 | CY19: 0 | CZ19: 0 | DA19: 0 | DB19: 0 | DC19: 0 | DD19: 0 | DE19: 0 | DF19: 0 | DG19: 0 | DH19: 0 | DI19: 0 | DJ19: 0 | DK19: 0 | DL19: 0 | DM19: 0 | DN19: 0 | DO19: 0 | DP19: 0 | DQ19: 0 | DR19: 0 | DS19: 0 | DT19: 0 | DU19: 0 | DV19: 0 | DW19: 0 | DX19: 0 | DY19: 0 | DZ19: 0 | EA19: 0 | EB19: 0 | EC19: 0 | ED19: 0 | EE19: 0 | EF19: 0 | EG19: 0 | EH19: 0 | EI19: 0 | EJ19: =SUM(D19:EI19) -> 95679.912
A20: 13 | B20: Code 13 | C20: Goods/ products industry 13 | D20: 0 | E20: 0 | F20: 0 | G20: 0 | H20: 0 | I20: 0 | J20: 0 | K20: 1.2001758e-05 | L20: 0 | M20: 0 | N20: 0.018286594 | O20: 51.010589 | P20: 65643.179 | Q20: 163.16188 | R20: 0.004123851 | S20: 0.030648651 | T20: 0 | U20: 0.02686908 | V20: 0.0041025469 | W20: 22.31183 | X20: 0.10101414 | Y20: 0.20558939 | Z20: 2.0963591e-05 | AA20: 0 | AB20: 0.010804756 | AC20: 0.0024986102 | AD20: 0 | AE20: 0.00034186558 | AF20: 0.12909721 | AG20: 0 | AH20: 7.0446255 | AI20: 1.4819948 | AJ20: 94.07767 | AK20: 0.60593004 | AL20: 0.34235194 | AM20: 0.065252563 | AN20: 0 | AO20: 0.0019303951 | AP20: 3192.4762 | AQ20: 0.20673455 | AR20: 3.1669018 | AS20: 0.002376158 | AT20: 0.063284163 | AU20: 0.00016227223 | AV20: 193.37501 | AW20: 0.020573546 | AX20: 0.0010525989 | AY20: 2.6984105 | AZ20: 127.49288 | BA20: 6.7126626 | BB20: 693.6913 | BC20: 2.4479434 | BD20: 1.0080202 | BE20: 24.927843 | BF20: 16.687604 | BG20: 3.2171548 | BH20: 5057.9967 | BI20: 3.9838661 | BJ20: 1.8494037 | BK20: 40.285153 | BL20: 214.69324 | BM20: 76.063043 | BN20: 1732.2364 | BO20: 3687588.4 | BP20: 530.95644 | BQ20: 5650.0563 | BR20: 433.63202 | BS20: 0.077955976 | BT20: 16.269455 | BU20: 0 | BV20: 40534.046 | BW20: 0.090723483 | BX20: 22.03754 | BY20: 0.00041742626 | BZ20: 2942.6784 | CA20: 1.2180446 | CB20: 0.32550901 | CC20: 0.57908509 | CD20: 0.17718153 | CE20: 5.5993577 | CF20: 4.8226402 | CG20: 306.51473 | CH20: 2.561977 | CI20: 0.49255853 | CJ20: 0.0050266055 | CK20: 10.113445 | CL20: 0.0074337427 | CM20: 0 | CN20: 0 | CO20: 0 | CP20: 272.20561 | CQ20: 2419.0693 | CR20: 28.288915 | CS20: 20.657414 | CT20: 0 | CU20: 0 | CV20: 0 | CW20: 0 | CX20: 0 | CY20: 0 | CZ20: 0 | DA20: 0 | DB20: 0 | DC20: 0 | DD20: 0 | DE20: 0 | DF20: 0 | DG20: 0 | DH20: 0 | DI20: 0 | DJ20: 0 | DK20: 0 | DL20: 0 | DM20: 0 | DN20: 0 | DO20: 0 | DP20: 0 | DQ20: 0 | DR20: 0 | DS20: 0 | DT20: 0 | DU20: 0 | DV20: 0 | DW20: 0 | DX20: 0 | DY20: 0 | DZ20: 0 | EA20: 0 | EB20: 0 | EC20: 0 | ED20: 0 | EE20: 0 | EF20: 0 | EG20: 0 | EH20: 0 | EI20: 0 | EJ20: =SUM(D20:EI20) -> 3818170
... A143: 136 | B143: Code 136 | C143: Goods/ products industry 136 | D143: 5.5399854 | E143: 0 | F143: 0.78328681 | G143: 0 | H143: 0 | I143: 0 | J143: 0 | K143: 0 | L143: 0 | M143: 0 | N143: 0 | O143: 0 | P143: 0.039556822 | Q143: 0.99989839 | R143: 0.015072741 | S143: 0.51725964 | T143: 0 | U143: 0.090532435 | V143: 0.61361399 | W143: 0.015077254 | X143: 0.017771648 | Y143: 0.31313221 | Z143: 0.0081299883 | AA143: 0 | AB143: 0 | AC143: 0.026470983 | AD143: 0 | AE143: 71.371594 | AF143: 53.264432 | AG143: 2.0378726 | AH143: 1291.7383 | AI143: 160.28572 | AJ143: 3.3803836 | AK143: 0.18736651 | AL143: 3.8917709 | AM143: 3.1401963 | AN143: 0 | AO143: 0.025943324 | AP143: 0.67776241 | AQ143: 0.00015277381 | AR143: 0.1540741 | AS143: 0 | AT143: 0.46387926 | AU143: 0.084064638 | AV143: 1.2286628 | AW143: 9.1299872 | AX143: 0.14273349 | AY143: 12.121448 | AZ143: 10.022052 | BA143: 1.2859787 | BB143: 1.3926634 | BC143: 5.1569842 | BD143: 0.60868751 | BE143: 0.34696616 | BF143: 0.093916309 | BG143: 0.013683802 | BH143: 0.0021827145 | BI143: 0.60673428 | BJ143: 0.20855848 | BK143: 0.072375633 | BL143: 1.7530795e-05 | BM143: 1.8480011 | BN143: 0.020097273 | BO143: 0.70384379 | BP143: 0.058599022 | BQ143: 3.8879876 | BR143: 8.8438877 | BS143: 0.26488171 | BT143: 0.069933887 | BU143: 0 | BV143: 0 | BW143: 0.041259969 | BX143: 0.029486421 | BY143: 0.53868183 | BZ143: 3.867186 | CA143: 9.9471443 | CB143: 2.5698734 | CC143: 1.3655894 | CD143: 0.0046709535 | CE143: 2716.2956 | CF143: 4.0161911 | CG143: 5.5519085 | CH143: 174.90321 | CI143: 0.0043902769 | CJ143: 5.79603 | CK143: 2.4568353 | CL143: 1529.2983 | CM143: 0 | CN143: 0 | CO143: 0.00015474459 | CP143: 18.304221 | CQ143: 0 | CR143: 0 | CS143: 0.91043894 | CT143: 0 | CU143: 0 | CV143: 6.1882227 | CW143: 0 | CX143: 0 | CY143: 0 | CZ143: 0 | DA143: 0 | DB143: 0 | DC143: 0 | DD143: 0 | DE143: 0 | DF143: 0 | DG143: 0 | DH143: 0 | DI143: 0 | DJ143: 0 | DK143: 0 | DL143: 0 | DM143: 0 | DN143: 0 | DO143: 33.357993 | DP143: 0 | DQ143: 0 | DR143: 0 | DS143: 0 | DT143: 0 | DU143: 0 | DV143: 0 | DW143: 0 | DX143: 2853.442 | DY143: 8905.4449 | DZ143: 2035.3598 | EA143: 891.10557 | EB143: 0 | EC143: 80.65188 | ED143: 83.764532 | EE143: 19.767349 | EF143: 134.18378 | EG143: 0.19547928 | EH143: 0 | EI143: 0 | EJ143: =SUM(D143:EI143) -> 21177.177
C144: Прямые покупки за рубежом, совершаемые резидентами | EJ144: =SUM(D144:EI144) -> 0
C145: Прмежуточное потребление | D145: =SUM(D8:D144) -> 4014939.8 | E145: =SUM(E8:E144) -> 7926897 | F145: =SUM(F8:F144) -> 3061342.9 | G145: =SUM(G8:G144) -> 1619400.6 | H145: =SUM(H8:H144) -> 21264394 | I145: =SUM(I8:I144) -> 6915349.8 | J145: =SUM(J8:J144) -> 802181.09 | K145: =SUM(K8:K144) -> 398353.09 | ... EJ145: =SUM(EJ8:EJ144) -> 1.9865524e+08
B146: Transferred from the next first pass tab | C146: Intermediate consumption after first iteration of primary eff | D146: ='primary effect'!EJ137 -> 12054912 | E146: ='primary effect'!EK137 -> 23798013 | F146: ='primary effect'!EL137 -> 9192745.6 | G146: ='primary effect'!EM137 -> 4861781.7 | H146: ='primary effect'!EN137 -> 63841658 | I146: ='primary effect'!EO137 -> 20765224 | J146: ='primary effect'!EP137 -> 2408918.9 | K146: ='primary effect'!EQ137 -> 1196335.3 | ... EI146: ='primary effect'!JO137 -> 2884294.2
C147: Intermediate consumption after second iteration | D147: ='secondary effect'!EJ137 -> 13466232 | E147: ='secondary effect'!EK137 -> 26274388 | F147: ='secondary effect'!EL137 -> 10356950 | G147: ='secondary effect'!EM137 -> 5382700.2 | H147: ='secondary effect'!EN137 -> 71057548 | I147: ='secondary effect'!EO137 -> 23170092 | J147: ='secondary effect'!EP137 -> 2608157 | K147: ='secondary effect'!EQ137 -> 1338955.2 | ... EI147: ='secondary effect'!JO137 -> 3187379.9
C148: Intermediate consumption after third iteration | D148: ='tertiary effect'!EJ137 -> 13722108 | E148: ='tertiary effect'!EK137 -> 26685932 | F148: ='tertiary effect'!EL137 -> 10566993 | G148: ='tertiary effect'!EM137 -> 5473445.2 | H148: ='tertiary effect'!EN137 -> 72344727 | I148: ='tertiary effect'!EO137 -> 23605446 | J148: ='tertiary effect'!EP137 -> 2637710.8 | K148: ='tertiary effect'!EQ137 -> 1365417.3 | ... EI148: ='tertiary effect'!JO137 -> 3246181.9
C149: Intermediate consumption after fourth iteration | D149: ='quadruple effect'!EJ137 -> 13769630 | E149: ='quadruple effect'!EK137 -> 26758483 | F149: ='quadruple effect'!EL137 -> 10605933 | G149: ='quadruple effect'!EM137 -> 5490016.5 | H149: ='quadruple effect'!EN137 -> 72582369 | I149: ='quadruple effect'!EO137 -> 23687740 | J149: ='quadruple effect'!EP137 -> 2642736.8 | K149: ='quadruple effect'!EQ137 -> 1370477.7 | ... EI149: ='quadruple effect'!JO137 -> 3257679.9
C150: Intermediate consumption after fifth iteration | D150: ='quintuple effect'!EJ137 -> 13778679 | E150: ='quintuple effect'!EK137 -> 26771959 | F150: ='quintuple effect'!EL137 -> 10613388 | G150: ='quintuple effect'!EM137 -> 5493159 | H150: ='quintuple effect'!EN137 -> 72627703 | I150: ='quintuple effect'!EO137 -> 23703984 | J150: ='quintuple effect'!EP137 -> 2643676 | K150: ='quintuple effect'!EQ137 -> 1371476.5 | ... EI150: ='quintuple effect'!JO137 -> 3259952.1
C151: change in intermediate consumption after first iteration | D151: =D146-D145 -> 8039971.9 | E151: =E146-E145 -> 15871116 | F151: =F146-F145 -> 6131402.7 | G151: =G146-G145 -> 3242381.1 | H151: =H146-H145 -> 42577263 | I151: =I146-I145 -> 13849875 | J151: =J146-J145 -> 1606737.8 | K151: =K146-K145 -> 797982.26 | ... EI151: =EI146-EI145 -> 1924672.3
C152: change in intermediate consumption after second iteration | D152: =D147-D146 -> 1411320.4 | E152: =E147-E146 -> 2476374.6 | F152: =F147-F146 -> 1164204.2 | G152: =G147-G146 -> 520918.46 | H152: =H147-H146 -> 7215890.4 | I152: =I147-I146 -> 2404867.2 | J152: =J147-J146 -> 199238.11 | K152: =K147-K146 -> 142619.89 | ... EI152: =EI147-EI146 -> 303085.71
C153: change in intermediate consumption after third iteration | D153: =D148-D147 -> 255875.88 | E153: =E148-E147 -> 411544.9 | F153: =F148-F147 -> 210042.65 | G153: =G148-G147 -> 90745.067 | H153: =H148-H147 -> 1287179.2 | I153: =I148-I147 -> 435354.23 | J153: =J148-J147 -> 29553.804 | K153: =K148-K147 -> 26462.113 | ... EI153: =EI148-EI147 -> 58802.082
C154: change in intermediate consumption after fourth iteration | D154: =D149-D148 -> 47521.788 | E154: =E149-E148 -> 72550.834 | F154: =F149-F148 -> 38940.696 | G154: =G149-G148 -> 16571.269 | H154: =H149-H148 -> 237641.38 | I154: =I149-I148 -> 82294.41 | J154: =J149-J148 -> 5025.9468 | K154: =K149-K148 -> 5060.3674 | ... EI154: =EI149-EI148 -> 11497.922
C155: change in intermediate consumption after fifth iteration | D155: =D150-D149 -> 9049.4629 | E155: =E150-E149 -> 13476.029 | F155: =F150-F149 -> 7454.7728 | G155: =G150-G149 -> 3142.5017 | H155: =H150-H149 -> 45334.886 | I155: =I150-I149 -> 16244.11 | J155: =J150-J149 -> 939.22142 | K155: =K150-K149 -> 998.73782 | ... EI155: =EI150-EI149 -> 2272.2712
C156: Чистые налоги на продукты | D156: 283099.6 | E156: 245163.71 | F156: 397058.56 | G156: 46952.291 | H156: 1058545 | I156: -549060.32 | J156: 43489.037 | K156: 28892.907 | L156: 38662.928 | M156: 161062.1 | N156: 821428.69 | O156: 21.871516 | P156: 296630.11 | Q156: 84481.304 | R156: 47672.149 | S156: 95323.462 | T156: 11881.088 | U156: 203597.75 | V156: 178954.99 | W156: 48565.802 | X156: 505783.37 | Y156: 222787.95 | Z156: 127953.49 | AA156: 78985.035 | AB156: 139001 | AC156: 446900.29 | AD156: 154874.02 | AE156: 787808.86 | AF156: 151963.53 | AG156: 21632.497 | AH156: 563600.59 | AI156: 387906.59 | AJ156: 90027.312 | AK156: 74615.588 | AL156: 154930.71 | AM156: 85349.564 | AN156: 25.144232 | AO156: 1089661 | AP156: 141823.76 | AQ156: 493450.37 | AR156: 440714.63 | AS156: 11763.731 | AT156: 48799.29 | AU156: 79042.914 | AV156: 44862.721 | AW156: 20615.5 | AX156: 61556.076 | AY156: 28835.492 | AZ156: 280744.28 | BA156: 148450.84 | BB156: 82649.014 | BC156: 41486.157 | BD156: 82752.508 | BE156: 16440.023 | BF156: 92313.633 | BG156: 10493.164 | BH156: 319579.96 | BI156: 315511.02 | BJ156: 10239.543 | BK156: 45035.896 | BL156: 313092.1 | BM156: 127412.68 | BN156: 72232.488 | BO156: 1867432.2 | BP156: 5329.8848 | BQ156: 263962.5 | BR156: 290357.39 | BS156: 306189.57 | BT156: 164674.82 | BU156: 8448.131 | BV156: 124680.99 | BW156: 63230.243 | BX156: 174439.06 | BY156: 44454.488 | BZ156: 172004.67 | CA156: 27594.569 | CB156: 15162.272 | CC156: 43136.69 | CD156: 859.15961 | CE156: 2749896.1 | CF156: 47539.202 | CG156: 170281.64 | CH156: 80582.276 | CI156: 8320.7397 | CJ156: 14682.573 | CK156: 97389.362 | CL156: 1305193.8 | CM156: 11095.786 | CN156: 1829.6208 | CO156: 84221.532 | CP156: 8658.0939 | CQ156: 32654.508 | CR156: 9136.4171 | CS156: 40896.668 | CT156: 64.78599 | CU156: 3430603 | CV156: 1492308.2 | CW156: 2548562 | CX156: 101830.46 | CY156: 10202.736 | CZ156: 37152.141 | DA156: 118457.08 | DB156: 9236.4535 | DC156: 3566.1583 | DD156: 25430.363 | DE156: 328298.93 | DF156: 39701.126 | DG156: 15587.788 | DH156: 207251.79 | DI156: 12879.187 | DJ156: 12221.777 | DK156: 323389.68 | DL156: 5459.8927 | DM156: 22143.64 | DN156: 76666.454 | DO156: 20149.132 | DP156: 59195.199 | DQ156: 7361.7521 | DR156: 1162.1448 | DS156: 106607.5 | DT156: 4154.6147 | DU156: -30206.449 | DV156: 18026.618 | DW156: 31981.182 | DX156: 34846.553 | DY156: -145662.29 | DZ156: -979834.31 | EA156: 183818.67 | EB156: 8311.6798 | EC156: 3522.5287 | ED156: 2667.5542 | EE156: 6225.4398 | EF156: 58128.812 | EG156: 44046.002 | EH156: 129967.06 | EI156: 130263.51 | EJ156: =SUM(D156:EI156) -> 28706209 | EK156: 15075914 | EL156: 0 | EM156: 0 | EN156: 0 | EO156: 7440489.3 | EP156: 770193.95 | EQ156: 0 | ER156: =SUM(EK156:EQ156) -> 23286597 | ES156: =EJ156+ER156 -> 51992806
C157: Прмежуточное потребление в ценах покупателей (original intermediate cdonsumption) | D157: =D145+D156 -> 4298039.4 | E157: =E145+E156 -> 8172060.7 | F157: =F145+F156 -> 3458401.5 | G157: =G145+G156 -> 1666352.9 | H157: =H145+H156 -> 22322939 | I157: =I145+I156 -> 6366289.4 | J157: =J145+J156 -> 845670.12 | K157: =K145+K156 -> 427246 | ... EI157: =EI145+EI156 -> 1089885.3 | EJ157: =SUM(D157:EI157) -> 2.2736145e+08 | EK157: =SUM(EK145:EK156) -> 15075914 | EL157: =SUM(EL145:EL156) -> 0 | EM157: =SUM(EM145:EM156) -> 0 | EN157: =SUM(EN145:EN156) -> 0 | EO157: =SUM(EO145:EO156) -> 7440489.3 | EP157: =SUM(EP145:EP156) -> 770193.95 | EQ157: =SUM(EQ145:EQ156) -> 0 | ER157: =SUM(ER145:ER156) -> 23286597 | ES157: =SUM(ES145:ES156) -> 51992806
C158: Оплата труда работников | D158: 1043801.6 | E158: 2019480.7 | F158: 815315.64 | G158: 412300.18 | H158: 5451078.2 | I158: 1697266.9 | J158: 206646.84 | K158: 127528.47 | L158: 342688.57 | M158: 626364.27 | N158: 2683838.5 | O158: 108.81919 | P158: 839722.19 | Q158: 276535.55 | R158: 246142.06 | S158: 439937.12 | T158: 15778.455 | U158: 266383.38 | V158: 377883.57 | W158: 243804.14 | X158: 628041.07 | Y158: 340563.64 | Z158: 124619.96 | AA158: 217792.37 | AB158: 154170.59 | AC158: 723082.06 | AD158: 137136.09 | AE158: 2147026.7 | AF158: 190393.1 | AG158: 28706.217 | AH158: 727658.8 | AI158: 1316759.9 | AJ158: 154921.99 | AK158: 119806.83 | AL158: 261439.79 | AM158: 278827.13 | AN158: 18.615913 | AO158: 786446.63 | AP158: 241112.39 | AQ158: 562082.53 | AR158: 511171.56 | AS158: 12576.958 | AT158: 93271.082 | AU158: 79326.497 | AV158: 64705.36 | AW158: 33665.883 | AX158: 275827.18 | AY158: 34675.241 | AZ158: 341674.89 | BA158: 145973.43 | BB158: 98700.615 | BC158: 49004.333 | BD158: 194995.05 | BE158: 38512.212 | BF158: 212681.49 | BG158: 26648.546 | BH158: 726434.88 | BI158: 746500.88 | BJ158: 41515.556 | BK158: 184248.87 | BL158: 969798.26 | BM158: 338484.78 | BN158: 210127.17 | BO158: 7406081.5 | BP158: 17114.005 | BQ158: 576890.21 | BR158: 527635.98 | BS158: 352417.33 | BT158: 205344.05 | BU158: 22133.657 | BV158: 224021.37 | BW158: 91559.38 | BX158: 251595.67 | BY158: 53386.707 | BZ158: 312849.41 | CA158: 35200.784 | CB158: 22622.904 | CC158: 83330.453 | CD158: 4373.6193 | CE158: 2039707.9 | CF158: 202162.4 | CG158: 285496.61 | CH158: 125024.18 | CI158: 13024.614 | CJ158: 29641.738 | CK158: 542045.09 | CL158: 2599986.5 | CM158: 32335.111 | CN158: 8081.6366 | CO158: 248517.26 | CP158: 1101176.3 | CQ158: 594645.31 | CR158: 176685.8 | CS158: 205440.16 | CT158: 1222.419 | CU158: 11050532 | CV158: 11585624 | CW158: 5196986 | CX158: 1663642.6 | CY158: 204170.55 | CZ158: 316437.94 | DA158: 966477.79 | DB158: 302965.01 | DC158: 58228.647 | DD158: 322167.89 | DE158: 1964673.9 | DF158: 633858.3 | DG158: 400036.24 | DH158: 6647148.7 | DI158: 605549.07 | DJ158: 199958.27 | DK158: 1085606.7 | DL158: 453735.24 | DM158: 95031.804 | DN158: 3276691.4 | DO158: 633649.65 | DP158: 171411.54 | DQ158: 139246.65 | DR158: 207250.36 | DS158: 136456.29 | DT158: 192780.58 | DU158: 78820.101 | DV158: 2981.7379 | DW158: 2290195.2 | DX158: 416216.65 | DY158: 28547130 | DZ158: 36040459 | EA158: 16045132 | EB158: 555698.51 | EC158: 337326.58 | ED158: 371588.05 | EE158: 406125.61 | EF158: 1227590.1 | EG158: 749420.55 | EH158: 198005.41 | EI158: 164216.6 | EJ158: =SUM(D158:EI158) -> 1.870367e+08 | EK158: 1.870367e+08 | EL158: =EK158-EJ158 -> -0.022736192
C159: заработная плата | D159: 910567.44 | E159: 1752913 | F159: 709983.77 | G159: 357877.32 | H159: 4731546.1 | I159: 1473508.5 | J159: 155510.43 | K159: 113507.1 | L159: 289757.14 | M159: 550868.01 | N159: 2358411.2 | O159: 98.500243 | P159: 760083.55 | Q159: 244832.18 | R159: 215822.89 | S159: 396443.56 | T159: 14218.717 | U159: 240023.75 | V159: 339338.98 | W159: 219704.51 | X159: 565814.75 | Y159: 306842.59 | Z159: 112235.18 | AA159: 196263.06 | AB159: 138891.85 | AC159: 654250.26 | AD159: 121070.77 | AE159: 1898078.5 | AF159: 168381.93 | AG159: 25510.092 | AH159: 644821.61 | AI159: 1197608.2 | AJ159: 141484.9 | AK159: 106855.45 | AL159: 232271.43 | AM159: 244108.67 | AN159: 16.076022 | AO159: 681441.82 | AP159: 210860.4 | AQ159: 487480.36 | AR159: 443405.61 | AS159: 10944.582 | AT159: 80909.119 | AU159: 69202.754 | AV159: 56357.091 | AW159: 29401.7 | AX159: 243328.42 | AY159: 30379.277 | AZ159: 299842.2 | BA159: 127609.21 | BB159: 86379.169 | BC159: 42845.857 | BD159: 170329.27 | BE159: 33650.751 | BF159: 185865.61 | BG159: 23277.546 | BH159: 636654.31 | BI159: 652226.23 | BJ159: 36355.681 | BK159: 160939.48 | BL159: 839656.48 | BM159: 293066.34 | BN159: 182680.3 | BO159: 6416386.2 | BP159: 14825.387 | BQ159: 505216.38 | BR159: 466269.72 | BS159: 297603.18 | BT159: 177948.05 | BU159: 19142.912 | BV159: 193778.27 | BW159: 78899.551 | BX159: 216318.8 | BY159: 46172.324 | BZ159: 263015.29 | CA159: 29740.559 | CB159: 19069.756 | CC159: 69801.785 | CD159: 3749.2708 | CE159: 1731602.3 | CF159: 176727.43 | CG159: 258077.38 | CH159: 114462.94 | CI159: 11810.122 | CJ159: 27162.563 | CK159: 477621.82 | CL159: 2272384.8 | CM159: 28261.008 | CN159: 7063.3416 | CO159: 217204.78 | CP159: 962459.29 | CQ159: 524386.12 | CR159: 155782.5 | CS159: 182914.44 | CT159: 1092.0179 | CU159: 10019165 | CV159: 10685081 | CW159: 4508889.2 | CX159: 1447024.3 | CY159: 183249.23 | CZ159: 295799.89 | DA159: 861975.87 | DB159: 280380.62 | DC159: 48605.525 | DD159: 278655.23 | DE159: 1681623.1 | DF159: 596476.83 | DG159: 361934.55 | DH159: 5811930.4 | DI159: 541919.25 | DJ159: 174910.17 | DK159: 896381.95 | DL159: 361666.27 | DM159: 74357.11 | DN159: 2662758.6 | DO159: 496136.05 | DP159: 151941.86 | DQ159: 126600.65 | DR159: 163520.64 | DS159: 114693.13 | DT159: 168722.61 | DU159: 71109.148 | DV159: 2259.319 | DW159: 1851740.1 | DX159: 360203.18 | DY159: 22836973 | DZ159: 28884011 | EA159: 12739254 | EB159: 438467.35 | EC159: 230288.81 | ED159: 296535.2 | EE159: 340453.25 | EF159: 1069161.6 | EG159: 661332.98 | EH159: 171487.04 | EI159: 133060.58 | EJ159: =SUM(D159:EI159) -> 1.577523e+08 | EK159: 1.577523e+08 | EL159: =EK159-EJ159 -> -0.019889295
C160: отчисления на социальное страхование 0 (social security contributions) | D160: 133234.2 | E160: 266567.69 | F160: 105331.87 | G160: 54422.855 | H160: 719532.17 | I160: 223758.4 | J160: 51136.409 | K160: 14021.374 | L160: 52931.423 | M160: 75496.256 | N160: 325427.39 | O160: 10.318944 | P160: 79638.635 | Q160: 31703.364 | R160: 30319.165 | S160: 43493.56 | T160: 1559.7375 | U160: 26359.626 | V160: 38544.589 | W160: 24099.632 | X160: 62226.318 | Y160: 33721.047 | Z160: 12384.777 | AA160: 21529.312 | AB160: 15278.74 | AC160: 68831.795 | AD160: 16065.318 | AE160: 248948.16 | AF160: 22011.175 | AG160: 3196.1251 | AH160: 82837.193 | AI160: 119151.69 | AJ160: 13437.087 | AK160: 12951.389 | AL160: 29168.358 | AM160: 34718.458 | AN160: 2.539891 | AO160: 105004.82 | AP160: 30251.992 | AQ160: 74602.167 | AR160: 67765.958 | AS160: 1632.3763 | AT160: 12361.963 | AU160: 10123.743 | AV160: 8348.2689 | AW160: 4264.1829 | AX160: 32498.762 | AY160: 4295.9642 | AZ160: 41832.696 | BA160: 18364.22 | BB160: 12321.446 | BC160: 6158.4759 | BD160: 24665.772 | BE160: 4861.4614 | BF160: 26815.874 | BG160: 3371.0005 | BH160: 89780.574 | BI160: 94274.645 | BJ160: 5159.8744 | BK160: 23309.383 | BL160: 130141.78 | BM160: 45418.431 | BN160: 27446.87 | BO160: 989695.25 | BP160: 2288.6171 | BQ160: 71673.832 | BR160: 61366.261 | BS160: 54814.15 | BT160: 27396.001 | BU160: 2990.7457 | BV160: 30243.109 | BW160: 12659.829 | BX160: 35276.877 | BY160: 7214.3825 | BZ160: 49834.129 | CA160: 5460.2255 | CB160: 3553.1487 | CC160: 13528.668 | CD160: 624.34849 | CE160: 308105.61 | CF160: 25434.977 | CG160: 27419.227 | CH160: 10561.234 | CI160: 1214.4915 | CJ160: 2479.1752 | CK160: 64423.261 | CL160: 327601.71 | CM160: 4074.103 | CN160: 1018.295 | CO160: 31312.48 | CP160: 138717.01 | CQ160: 70259.183 | CR160: 20903.301 | CS160: 22525.712 | CT160: 130.40109 | CU160: 1031367 | CV160: 900543.16 | CW160: 688096.79 | CX160: 216618.34 | CY160: 20921.316 | CZ160: 20638.05 | DA160: 104501.91 | DB160: 22584.391 | DC160: 9623.1218 | DD160: 43512.653 | DE160: 283050.78 | DF160: 37381.469 | DG160: 38101.688 | DH160: 835218.36 | DI160: 63629.815 | DJ160: 25048.101 | DK160: 189224.72 | DL160: 92068.967 | DM160: 20674.694 | DN160: 613932.85 | DO160: 137513.6 | DP160: 19469.678 | DQ160: 12646.004 | DR160: 43729.721 | DS160: 21763.161 | DT160: 24057.974 | DU160: 7710.9526 | DV160: 722.41889 | DW160: 438455.1 | DX160: 56013.467 | DY160: 5710156.9 | DZ160: 7156447.9 | EA160: 3305877.8 | EB160: 117231.16 | EC160: 107037.77 | ED160: 75052.855 | EE160: 65672.361 | EF160: 158428.47 | EG160: 88087.569 | EH160: 26518.362 | EI160: 31156.022 | EJ160: =SUM(D160:EI160) -> 29284408 | EK160: 29284408 | EL160: =EK160-EJ160 -> -0.0028468147
B161: 1.35 | C161: отчисления на социальное страхование 1 | D161: =D160*$B$161 -> 179866.16 | E161: =E160*$B$161 -> 359866.38 | F161: =F160*$B$161 -> 142198.02 | G161: =G160*$B$161 -> 73470.854 | H161: =H160*$B$161 -> 971368.43 | I161: =I160*$B$161 -> 302073.84 | J161: =J160*$B$161 -> 69034.152 | K161: =K160*$B$161 -> 18928.856 | ... EI161: =EI160*$B$161 -> 42060.63
C162: Другие налоги на производство | D162: 155183.64 | E162: 345514.9 | F162: 126741.85 | G162: 70540.835 | H162: 932630.24 | I162: 289504.63 | J162: 49700.561 | K162: 39881.552 | L162: 5876.9667 | M162: 29443.401 | N162: 131358.31 | O162: 6.9460965 | P162: 53599.16 | Q162: 14984.847 | R162: 7536.5495 | S162: 29875.374 | T162: 1071.6473 | U162: 18084.735 | V162: 26112.293 | W162: 16549.341 | X162: 42606.775 | Y162: 23008.724 | Z162: 8469.2306 | AA162: 14792.014 | AB162: 10482.735 | AC162: 51843.027 | AD162: 10646.187 | AE162: 161460.44 | AF162: 14188.463 | AG162: 1966.8089 | AH162: 52214.818 | AI162: 49713.613 | AJ162: 8260.6625 | AK162: 9081.1147 | AL162: 15573.127 | AM162: 7881.7892 | AN162: 2.171227 | AO162: 79977.964 | AP162: 17765.239 | AQ162: 43925.877 | AR162: 39808.647 | AS162: 968.56009 | AT162: 6915.3088 | AU162: 6053.6836 | AV162: 4429.2578 | AW162: 2592.8946 | AX162: 19370.592 | AY162: 2772.6626 | AZ162: 25923.924 | BA162: 12556.886 | BB162: 7819.2571 | BC162: 3919.3712 | BD162: 9564.77 | BE162: 1886.5872 | BF162: 10368.596 | BG162: 1317.755 | BH162: 36439.774 | BI162: 36585.129 | BJ162: 2054.6683 | BK162: 9035.3161 | BL162: 54600.363 | BM162: 19407.291 | BN162: 11883.396 | BO162: 412896.39 | BP162: 961.61644 | BQ162: 31330.372 | BR162: 28474.389 | BS162: 26755.358 | BT162: 13818.099 | BU162: 1569.7941 | BV162: 14537.573 | BW162: 6256.7122 | BX162: 18027.077 | BY162: 3740.0952 | BZ162: 16390.17 | CA162: 2007.4295 | CB162: 1364.7245 | CC162: 4229.3406 | CD162: 163.04911 | CE162: 162782.58 | CF162: 5270.8698 | CG162: 13136.465 | CH162: 4681.915 | CI162: 484.792 | CJ162: 1159.5535 | CK162: 11497.669 | CL162: 91252.645 | CM162: 1136.6425 | CN162: 283.5792 | CO162: 8718.5498 | CP162: 39169.516 | CQ162: 6978.3277 | CR162: 2074.0355 | CS162: 5014.1829 | CT162: 12.280053 | CU162: 442705.11 | CV162: 185593.26 | CW162: 160554.34 | CX162: 25240.838 | CY162: 2232.7904 | CZ162: 6182.4331 | DA162: 30720.173 | DB162: 4338.3091 | DC162: 880.72512 | DD162: 3614.5412 | DE162: 62033.805 | DF162: 13770.752 | DG162: 7056.105 | DH162: 93754.202 | DI162: 8981.1059 | DJ162: 2708.2487 | DK162: 1986778 | DL162: 4533.1179 | DM162: 4128.5044 | DN162: 32385.195 | DO162: 1207.5796 | DP162: 7374.455 | DQ162: 3137.6901 | DR162: 331.39293 | DS162: 9149.6673 | DT162: 1685.4263 | DU162: 1641.0766 | DV162: 6461.6542 | DW162: 3193.0839 | DX162: 9476.7426 | DY162: 213.58266 | DZ162: 54343.076 | EA162: 24504.686 | EB162: 13.901481 | EC162: 2.0908371 | ED162: 424.0602 | EE162: 324.1708 | EF162: 2597.896 | EG162: 783.66389 | EH162: 3439.2382 | EI162: 2071.9053 | EJ162: =SUM(D162:EI162) -> 7441077.7 | EK162: 7441077.7 | EL162: =EK162-EJ162 -> -0.0012614671
